1
2
3
4
5
6
7
--- Logging error ---
Traceback (most recent call last):
  File "C:\Python39\lib\logging\__init__.py", line 1086, in emit
    stream.write(msg + self.terminator)
  File "C:\Python39\lib\encodings\cp1252.py", line 19, in encode
    return codecs.charmap_encode(input,self.errors,encoding_table)[0]
UnicodeEncodeError: 'charmap' codec can't encode character '\u2205' in position 186: character maps to <undefined>
Call stack:
  File "C:\Python39\lib\threading.py", line 912, in _bootstrap
    self._bootstrap_inner()
  File "C:\Python39\lib\threading.py", line 954, in _bootstrap_inner
    self.run()
  File "C:\Python39\lib\threading.py", line 892, in run
    self._target(*self._args, **self._kwargs)
  File "C:\Python39\lib\socketserver.py", line 683, in process_request_thread
    self.finish_request(request, client_address)
  File "C:\Python39\lib\socketserver.py", line 360, in finish_request
    self.RequestHandlerClass(request, client_address, self)
  File "C:\Python39\lib\socketserver.py", line 747, in __init__
    self.handle()
  File "C:\Python39\lib\site-packages\django\core\servers\basehttp.py", line 154, in handle
    handler.run(self.server.get_app())
  File "C:\Python39\lib\wsgiref\handlers.py", line 137, in run
    self.result = application(self.environ, self.start_response)
  File "C:\Python39\lib\site-packages\django\contrib\staticfiles\handlers.py", line 65, in __call__
    return self.application(environ, start_response)
  File "C:\Python39\lib\site-packages\django\core\handlers\wsgi.py", line 142, in __call__
    response = self.get_response(request)
  File "C:\Python39\lib\site-packages\django\core\handlers\base.py", line 78, in get_response
    response = self._middleware_chain(request)
  File "C:\Python39\lib\site-packages\django\core\handlers\exception.py", line 34, in inner
    response = get_response(request)
  File "C:\Python39\lib\site-packages\django\utils\deprecation.py", line 91, in __call__
    response = response or self.get_response(request)
  File "C:\Python39\lib\site-packages\django\core\handlers\exception.py", line 34, in inner
    response = get_response(request)
  File "C:\Python39\lib\site-packages\django\utils\deprecation.py", line 91, in __call__
    response = response or self.get_response(request)
  File "C:\Python39\lib\site-packages\django\core\handlers\exception.py", line 34, in inner
    response = get_response(request)
  File "C:\Python39\lib\site-packages\django\utils\deprecation.py", line 91, in __call__
    response = response or self.get_response(request)
  File "C:\Python39\lib\site-packages\django\core\handlers\exception.py", line 34, in inner
    response = get_response(request)
  File "C:\Python39\lib\site-packages\django\utils\deprecation.py", line 91, in __call__
    response = response or self.get_response(request)
  File "C:\Python39\lib\site-packages\django\core\handlers\exception.py", line 34, in inner
    response = get_response(request)
  File "C:\Python39\lib\site-packages\django\utils\deprecation.py", line 91, in __call__
    response = response or self.get_response(request)
  File "C:\Python39\lib\site-packages\django\core\handlers\exception.py", line 34, in inner
    response = get_response(request)
  File "C:\Python39\lib\site-packages\django\utils\deprecation.py", line 91, in __call__
    response = response or self.get_response(request)
  File "C:\Python39\lib\site-packages\django\core\handlers\exception.py", line 34, in inner
    response = get_response(request)
  File "C:\Python39\lib\site-packages\django\utils\deprecation.py", line 91, in __call__
    response = response or self.get_response(request)
  File "C:\Python39\lib\site-packages\django\core\handlers\exception.py", line 34, in inner
    response = get_response(request)
  File "C:\Python39\lib\site-packages\django\core\handlers\base.py", line 124, in _get_response
    response = wrapped_callback(request, *callback_args, **callback_kwargs)
  File "C:\Users\Dell\Documents\mimamsaExamPortal\examPortal\examPortalApp\views.py", line 103, in automated_correction
    answer.save()
  File "C:\Python39\lib\site-packages\django\db\models\base.py", line 717, in save
    self.save_base(using=using, force_insert=force_insert,
  File "C:\Python39\lib\site-packages\django\db\models\base.py", line 748, in save_base
    updated = self._save_table(raw, cls, force_insert, force_update, using, update_fields)
  File "C:\Python39\lib\site-packages\django\db\models\base.py", line 811, in _save_table
    updated = self._do_update(base_qs, using, pk_val, values, update_fields,
  File "C:\Python39\lib\site-packages\django\db\models\base.py", line 861, in _do_update
    return filtered._update(values) > 0
  File "C:\Python39\lib\site-packages\django\db\models\query.py", line 712, in _update
    return query.get_compiler(self.db).execute_sql(CURSOR)
  File "C:\Python39\lib\site-packages\django\db\models\sql\compiler.py", line 1383, in execute_sql
    cursor = super().execute_sql(result_type)
  File "C:\Python39\lib\site-packages\django\db\models\sql\compiler.py", line 1065, in execute_sql
    cursor.execute(sql, params)
  File "C:\Python39\lib\site-packages\django\db\backends\utils.py", line 109, in execute
    logger.debug(
Message: '(%.3f) %s; args=%s'
Arguments: (0.08366084098815918, 'UPDATE "examPortalApp_answer" SET "team_instance_id" = \'TNP10432\', "question_instance_id" = 63, "answer_content" = \'[[4], \'\'∅=n*walength\\r\\n∅=n*(speed of light)/frequency\\r\\nfrequency of sound=speed of light*n/∅\\r\\nfrequency of sound= speed of light*n/π\\r\\n(∅=π)\\r\\nfrom A sound wave travels in clockwise and anticlockwise.\'\']\', "status" = \'a\', "marks" = 0 WHERE "examPortalApp_answer"."id" = 13652', ('TNP10432', 63, "[[4], '∅=n*walength\\r\\n∅=n*(speed of light)/frequency\\r\\nfrequency of sound=speed of light*n/∅\\r\\nfrequency of sound= speed of light*n/π\\r\\n(∅=π)\\r\\nfrom A sound wave travels in clockwise and anticlockwise.']", 'a', 0, 13652))
--- Logging error ---
Traceback (most recent call last):
  File "C:\Python39\lib\logging\__init__.py", line 1086, in emit
    stream.write(msg + self.terminator)
  File "C:\Python39\lib\encodings\cp1252.py", line 19, in encode
    return codecs.charmap_encode(input,self.errors,encoding_table)[0]
UnicodeEncodeError: 'charmap' codec can't encode character '\u03c0' in position 826: character maps to <undefined>
Call stack:
  File "C:\Python39\lib\threading.py", line 912, in _bootstrap
    self._bootstrap_inner()
  File "C:\Python39\lib\threading.py", line 954, in _bootstrap_inner
    self.run()
  File "C:\Python39\lib\threading.py", line 892, in run
    self._target(*self._args, **self._kwargs)
  File "C:\Python39\lib\socketserver.py", line 683, in process_request_thread
    self.finish_request(request, client_address)
  File "C:\Python39\lib\socketserver.py", line 360, in finish_request
    self.RequestHandlerClass(request, client_address, self)
  File "C:\Python39\lib\socketserver.py", line 747, in __init__
    self.handle()
  File "C:\Python39\lib\site-packages\django\core\servers\basehttp.py", line 154, in handle
    handler.run(self.server.get_app())
  File "C:\Python39\lib\wsgiref\handlers.py", line 137, in run
    self.result = application(self.environ, self.start_response)
  File "C:\Python39\lib\site-packages\django\contrib\staticfiles\handlers.py", line 65, in __call__
    return self.application(environ, start_response)
  File "C:\Python39\lib\site-packages\django\core\handlers\wsgi.py", line 142, in __call__
    response = self.get_response(request)
  File "C:\Python39\lib\site-packages\django\core\handlers\base.py", line 78, in get_response
    response = self._middleware_chain(request)
  File "C:\Python39\lib\site-packages\django\core\handlers\exception.py", line 34, in inner
    response = get_response(request)
  File "C:\Python39\lib\site-packages\django\utils\deprecation.py", line 91, in __call__
    response = response or self.get_response(request)
  File "C:\Python39\lib\site-packages\django\core\handlers\exception.py", line 34, in inner
    response = get_response(request)
  File "C:\Python39\lib\site-packages\django\utils\deprecation.py", line 91, in __call__
    response = response or self.get_response(request)
  File "C:\Python39\lib\site-packages\django\core\handlers\exception.py", line 34, in inner
    response = get_response(request)
  File "C:\Python39\lib\site-packages\django\utils\deprecation.py", line 91, in __call__
    response = response or self.get_response(request)
  File "C:\Python39\lib\site-packages\django\core\handlers\exception.py", line 34, in inner
    response = get_response(request)
  File "C:\Python39\lib\site-packages\django\utils\deprecation.py", line 91, in __call__
    response = response or self.get_response(request)
  File "C:\Python39\lib\site-packages\django\core\handlers\exception.py", line 34, in inner
    response = get_response(request)
  File "C:\Python39\lib\site-packages\django\utils\deprecation.py", line 91, in __call__
    response = response or self.get_response(request)
  File "C:\Python39\lib\site-packages\django\core\handlers\exception.py", line 34, in inner
    response = get_response(request)
  File "C:\Python39\lib\site-packages\django\utils\deprecation.py", line 91, in __call__
    response = response or self.get_response(request)
  File "C:\Python39\lib\site-packages\django\core\handlers\exception.py", line 34, in inner
    response = get_response(request)
  File "C:\Python39\lib\site-packages\django\utils\deprecation.py", line 91, in __call__
    response = response or self.get_response(request)
  File "C:\Python39\lib\site-packages\django\core\handlers\exception.py", line 34, in inner
    response = get_response(request)
  File "C:\Python39\lib\site-packages\django\core\handlers\base.py", line 124, in _get_response
    response = wrapped_callback(request, *callback_args, **callback_kwargs)
  File "C:\Users\Dell\Documents\mimamsaExamPortal\examPortal\examPortalApp\views.py", line 103, in automated_correction
    answer.save()
  File "C:\Python39\lib\site-packages\django\db\models\base.py", line 717, in save
    self.save_base(using=using, force_insert=force_insert,
  File "C:\Python39\lib\site-packages\django\db\models\base.py", line 748, in save_base
    updated = self._save_table(raw, cls, force_insert, force_update, using, update_fields)
  File "C:\Python39\lib\site-packages\django\db\models\base.py", line 811, in _save_table
    updated = self._do_update(base_qs, using, pk_val, values, update_fields,
  File "C:\Python39\lib\site-packages\django\db\models\base.py", line 861, in _do_update
    return filtered._update(values) > 0
  File "C:\Python39\lib\site-packages\django\db\models\query.py", line 712, in _update
    return query.get_compiler(self.db).execute_sql(CURSOR)
  File "C:\Python39\lib\site-packages\django\db\models\sql\compiler.py", line 1383, in execute_sql
    cursor = super().execute_sql(result_type)
  File "C:\Python39\lib\site-packages\django\db\models\sql\compiler.py", line 1065, in execute_sql
    cursor.execute(sql, params)
  File "C:\Python39\lib\site-packages\django\db\backends\utils.py", line 109, in execute
    logger.debug(
Message: '(%.3f) %s; args=%s'
Arguments: (0.07836723327636719, 'UPDATE "examPortalApp_answer" SET "team_instance_id" = \'GOM10160\', "question_instance_id" = 63, "answer_content" = \'[[3], "The boy is in the centre of the circle, and the people are on a circle around him; and the physicist is on the same plane very far from the boy. Since light\'\'s speed is finite, even though the people all respond at the same time, the information that the first person responded reaches the physicist before the response of the others. Thus, he sees a wave (W) which starts from the first person and ends at the last.\\r\\n\\r\\nThe physicist sees the speed as greater than c, as the light from person distant to him needs to cross the length equal to diameter (2r), while the physicist sees the wave move a distance equal to the semi-perimeter (πr), and since π > 2, he sees it move a greater distance than light. Thus, he sees it move at a speed greater than c."]\', "status" = \'a\', "marks" = 0 WHERE "examPortalApp_answer"."id" = 8464', ('GOM10160', 63, '[[3], "The boy is in the centre of the circle, and the people are on a circle around him; and the physicist is on the same plane very far from the boy. Since light\'s speed is finite, even though the people all respond at the same time, the information that the first person responded reaches the physicist before the response of the others. Thus, he sees a wave (W) which starts from the first person and ends at the last.\\r\\n\\r\\nThe physicist sees the speed as greater than c, as the light from person distant to him needs to cross the length equal to diameter (2r), while the physicist sees the wave move a distance equal to the semi-perimeter (πr), and since π > 2, he sees it move a greater distance than light. Thus, he sees it move at a speed greater than c."]', 'a', 0, 8464))
8
9
10
11
12
13
--- Logging error ---
Traceback (most recent call last):
  File "C:\Python39\lib\logging\__init__.py", line 1086, in emit
    stream.write(msg + self.terminator)
  File "C:\Python39\lib\encodings\cp1252.py", line 19, in encode
    return codecs.charmap_encode(input,self.errors,encoding_table)[0]
UnicodeEncodeError: 'charmap' codec can't encode character '\u2081' in position 225: character maps to <undefined>
Call stack:
  File "C:\Python39\lib\threading.py", line 912, in _bootstrap
    self._bootstrap_inner()
  File "C:\Python39\lib\threading.py", line 954, in _bootstrap_inner
    self.run()
  File "C:\Python39\lib\threading.py", line 892, in run
    self._target(*self._args, **self._kwargs)
  File "C:\Python39\lib\socketserver.py", line 683, in process_request_thread
    self.finish_request(request, client_address)
  File "C:\Python39\lib\socketserver.py", line 360, in finish_request
    self.RequestHandlerClass(request, client_address, self)
  File "C:\Python39\lib\socketserver.py", line 747, in __init__
    self.handle()
  File "C:\Python39\lib\site-packages\django\core\servers\basehttp.py", line 154, in handle
    handler.run(self.server.get_app())
  File "C:\Python39\lib\wsgiref\handlers.py", line 137, in run
    self.result = application(self.environ, self.start_response)
  File "C:\Python39\lib\site-packages\django\contrib\staticfiles\handlers.py", line 65, in __call__
    return self.application(environ, start_response)
  File "C:\Python39\lib\site-packages\django\core\handlers\wsgi.py", line 142, in __call__
    response = self.get_response(request)
  File "C:\Python39\lib\site-packages\django\core\handlers\base.py", line 78, in get_response
    response = self._middleware_chain(request)
  File "C:\Python39\lib\site-packages\django\core\handlers\exception.py", line 34, in inner
    response = get_response(request)
  File "C:\Python39\lib\site-packages\django\utils\deprecation.py", line 91, in __call__
    response = response or self.get_response(request)
  File "C:\Python39\lib\site-packages\django\core\handlers\exception.py", line 34, in inner
    response = get_response(request)
  File "C:\Python39\lib\site-packages\django\utils\deprecation.py", line 91, in __call__
    response = response or self.get_response(request)
  File "C:\Python39\lib\site-packages\django\core\handlers\exception.py", line 34, in inner
    response = get_response(request)
  File "C:\Python39\lib\site-packages\django\utils\deprecation.py", line 91, in __call__
    response = response or self.get_response(request)
  File "C:\Python39\lib\site-packages\django\core\handlers\exception.py", line 34, in inner
    response = get_response(request)
  File "C:\Python39\lib\site-packages\django\utils\deprecation.py", line 91, in __call__
    response = response or self.get_response(request)
  File "C:\Python39\lib\site-packages\django\core\handlers\exception.py", line 34, in inner
    response = get_response(request)
  File "C:\Python39\lib\site-packages\django\utils\deprecation.py", line 91, in __call__
    response = response or self.get_response(request)
  File "C:\Python39\lib\site-packages\django\core\handlers\exception.py", line 34, in inner
    response = get_response(request)
  File "C:\Python39\lib\site-packages\django\utils\deprecation.py", line 91, in __call__
    response = response or self.get_response(request)
  File "C:\Python39\lib\site-packages\django\core\handlers\exception.py", line 34, in inner
    response = get_response(request)
  File "C:\Python39\lib\site-packages\django\utils\deprecation.py", line 91, in __call__
    response = response or self.get_response(request)
  File "C:\Python39\lib\site-packages\django\core\handlers\exception.py", line 34, in inner
    response = get_response(request)
  File "C:\Python39\lib\site-packages\django\core\handlers\base.py", line 124, in _get_response
    response = wrapped_callback(request, *callback_args, **callback_kwargs)
  File "C:\Users\Dell\Documents\mimamsaExamPortal\examPortal\examPortalApp\views.py", line 103, in automated_correction
    answer.save()
  File "C:\Python39\lib\site-packages\django\db\models\base.py", line 717, in save
    self.save_base(using=using, force_insert=force_insert,
  File "C:\Python39\lib\site-packages\django\db\models\base.py", line 748, in save_base
    updated = self._save_table(raw, cls, force_insert, force_update, using, update_fields)
  File "C:\Python39\lib\site-packages\django\db\models\base.py", line 811, in _save_table
    updated = self._do_update(base_qs, using, pk_val, values, update_fields,
  File "C:\Python39\lib\site-packages\django\db\models\base.py", line 861, in _do_update
    return filtered._update(values) > 0
  File "C:\Python39\lib\site-packages\django\db\models\query.py", line 712, in _update
    return query.get_compiler(self.db).execute_sql(CURSOR)
  File "C:\Python39\lib\site-packages\django\db\models\sql\compiler.py", line 1383, in execute_sql
    cursor = super().execute_sql(result_type)
  File "C:\Python39\lib\site-packages\django\db\models\sql\compiler.py", line 1065, in execute_sql
    cursor.execute(sql, params)
  File "C:\Python39\lib\site-packages\django\db\backends\utils.py", line 109, in execute
    logger.debug(
Message: '(%.3f) %s; args=%s'
Arguments: (0.08316445350646973, 'UPDATE "examPortalApp_answer" SET "team_instance_id" = \'RMA10467\', "question_instance_id" = 55, "answer_content" = \'[[4], \'\'As A1 A2, A3 An the pocations.\\r\\n\\r\\nK₁, K2, K3,- kn are activation coefficient\\r\\n\\r\\nthe enzymes. X is the initative protein.\\r\\n\\r\\nK1>k2 >K3> ... > K\\r\\n\\r\\nAs in the diagram,\\r\\n\\r\\ndue to k1 the z. enzyme is there due to A1 is form product Pormed and from K2,z2 eneyme from the A2 product and so on.\'\']\', "status" = \'a\', "marks" = 0 WHERE "examPortalApp_answer"."id" = 11968', ('RMA10467', 55, "[[4], 'As A1 A2, A3 An the pocations.\\r\\n\\r\\nK₁, K2, K3,- kn are activation coefficient\\r\\n\\r\\nthe enzymes. X is the initative protein.\\r\\n\\r\\nK1>k2 >K3> ... > K\\r\\n\\r\\nAs in the diagram,\\r\\n\\r\\ndue to k1 the z. enzyme is there due to A1 is form product Pormed and from K2,z2 eneyme from the A2 product and so on.']", 'a', 0, 11968))
14
15
16
17
18
19
--- Logging error ---
Traceback (most recent call last):
  File "C:\Python39\lib\logging\__init__.py", line 1086, in emit
    stream.write(msg + self.terminator)
  File "C:\Python39\lib\encodings\cp1252.py", line 19, in encode
    return codecs.charmap_encode(input,self.errors,encoding_table)[0]
UnicodeEncodeError: 'charmap' codec can't encode character '\u03b4' in position 847: character maps to <undefined>
Call stack:
  File "C:\Python39\lib\threading.py", line 912, in _bootstrap
    self._bootstrap_inner()
  File "C:\Python39\lib\threading.py", line 954, in _bootstrap_inner
    self.run()
  File "C:\Python39\lib\threading.py", line 892, in run
    self._target(*self._args, **self._kwargs)
  File "C:\Python39\lib\socketserver.py", line 683, in process_request_thread
    self.finish_request(request, client_address)
  File "C:\Python39\lib\socketserver.py", line 360, in finish_request
    self.RequestHandlerClass(request, client_address, self)
  File "C:\Python39\lib\socketserver.py", line 747, in __init__
    self.handle()
  File "C:\Python39\lib\site-packages\django\core\servers\basehttp.py", line 154, in handle
    handler.run(self.server.get_app())
  File "C:\Python39\lib\wsgiref\handlers.py", line 137, in run
    self.result = application(self.environ, self.start_response)
  File "C:\Python39\lib\site-packages\django\contrib\staticfiles\handlers.py", line 65, in __call__
    return self.application(environ, start_response)
  File "C:\Python39\lib\site-packages\django\core\handlers\wsgi.py", line 142, in __call__
    response = self.get_response(request)
  File "C:\Python39\lib\site-packages\django\core\handlers\base.py", line 78, in get_response
    response = self._middleware_chain(request)
  File "C:\Python39\lib\site-packages\django\core\handlers\exception.py", line 34, in inner
    response = get_response(request)
  File "C:\Python39\lib\site-packages\django\utils\deprecation.py", line 91, in __call__
    response = response or self.get_response(request)
  File "C:\Python39\lib\site-packages\django\core\handlers\exception.py", line 34, in inner
    response = get_response(request)
  File "C:\Python39\lib\site-packages\django\utils\deprecation.py", line 91, in __call__
    response = response or self.get_response(request)
  File "C:\Python39\lib\site-packages\django\core\handlers\exception.py", line 34, in inner
    response = get_response(request)
  File "C:\Python39\lib\site-packages\django\utils\deprecation.py", line 91, in __call__
    response = response or self.get_response(request)
  File "C:\Python39\lib\site-packages\django\core\handlers\exception.py", line 34, in inner
    response = get_response(request)
  File "C:\Python39\lib\site-packages\django\utils\deprecation.py", line 91, in __call__
    response = response or self.get_response(request)
  File "C:\Python39\lib\site-packages\django\core\handlers\exception.py", line 34, in inner
    response = get_response(request)
  File "C:\Python39\lib\site-packages\django\utils\deprecation.py", line 91, in __call__
    response = response or self.get_response(request)
  File "C:\Python39\lib\site-packages\django\core\handlers\exception.py", line 34, in inner
    response = get_response(request)
  File "C:\Python39\lib\site-packages\django\utils\deprecation.py", line 91, in __call__
    response = response or self.get_response(request)
  File "C:\Python39\lib\site-packages\django\core\handlers\exception.py", line 34, in inner
    response = get_response(request)
  File "C:\Python39\lib\site-packages\django\utils\deprecation.py", line 91, in __call__
    response = response or self.get_response(request)
  File "C:\Python39\lib\site-packages\django\core\handlers\exception.py", line 34, in inner
    response = get_response(request)
  File "C:\Python39\lib\site-packages\django\core\handlers\base.py", line 124, in _get_response
    response = wrapped_callback(request, *callback_args, **callback_kwargs)
  File "C:\Users\Dell\Documents\mimamsaExamPortal\examPortal\examPortalApp\views.py", line 103, in automated_correction
    answer.save()
  File "C:\Python39\lib\site-packages\django\db\models\base.py", line 717, in save
    self.save_base(using=using, force_insert=force_insert,
  File "C:\Python39\lib\site-packages\django\db\models\base.py", line 748, in save_base
    updated = self._save_table(raw, cls, force_insert, force_update, using, update_fields)
  File "C:\Python39\lib\site-packages\django\db\models\base.py", line 811, in _save_table
    updated = self._do_update(base_qs, using, pk_val, values, update_fields,
  File "C:\Python39\lib\site-packages\django\db\models\base.py", line 861, in _do_update
    return filtered._update(values) > 0
  File "C:\Python39\lib\site-packages\django\db\models\query.py", line 712, in _update
    return query.get_compiler(self.db).execute_sql(CURSOR)
  File "C:\Python39\lib\site-packages\django\db\models\sql\compiler.py", line 1383, in execute_sql
    cursor = super().execute_sql(result_type)
  File "C:\Python39\lib\site-packages\django\db\models\sql\compiler.py", line 1065, in execute_sql
    cursor.execute(sql, params)
  File "C:\Python39\lib\site-packages\django\db\backends\utils.py", line 109, in execute
    logger.debug(
Message: '(%.3f) %s; args=%s'
Arguments: (0.08474469184875488, 'UPDATE "examPortalApp_answer" SET "team_instance_id" = \'BEN10129\', "question_instance_id" = 61, "answer_content" = \'[[4], \'\'Now, for clarity, it shall be assumed that I have the freedom to do one process at a time. This means that I can expand the system while assuming that the walls are not permeable, and then allow the walls to be permeable once the expansion is done. Note that this is plausible in the differential limit, and as an approximation, this separation shall be employed for small changes only. \\r\\n\\r\\nNow, since the system and env are both at 2 atm pressure, there is no impetus for the molecules to come into or out of the system (note that this motion will happen, but it will not change the system). Now assume we expanded the system by causing a change in volume δV. Now, corresponding to this, there will be a small change δP in the pressure following the Ideal Gas eq in Isothermal conditions (PV = const.). Now the pressure inside the system is 2-δP < 2. Hence, for a gas molecule attempting to leave the system, there is higher resistance to go outside. Similarly, for a gas molecule entering, there is a net force pushing it into the system This continues till pressure is equalised. Assuming the environment is infinite, there is no way to expand he volume to  halve the pressure. \\r\\n\\r\\nSince the pressure inside and outside the system is the same, the gas molecules will never spontaneously leave the system such that pressure inside is half of the environment pressure. \\r\\n\\r\\nHence, there is no possible way for the system and environment to be in equilibrium in a state where the pressure of the system is 1atm and the environment is 2atm. With the system, the only equilibrium is possible at 2 atm no matter how the change is carries, as we are allowing the change of 2 quantities, n, the number of moles and V, the volume. Hence, the two will balance themselves out. \\r\\nHence equilibrium at the given final state can never be achieved.\'\']\', "status" = \'a\', "marks" = 0 WHERE "examPortalApp_answer"."id" = 11201', ('BEN10129', 61, "[[4], 'Now, for clarity, it shall be assumed that I have the freedom to do one process at a time. This means that I can expand the system while assuming that the walls are not permeable, and then allow the walls to be permeable once the expansion is done. Note that this is plausible in the differential limit, and as an approximation, this separation shall be employed for small changes only. \\r\\n\\r\\nNow, since the system and env are both at 2 atm pressure, there is no impetus for the molecules to come into or out of the system (note that this motion will happen, but it will not change the system). Now assume we expanded the system by causing a change in volume δV. Now, corresponding to this, there will be a small change δP in the pressure following the Ideal Gas eq in Isothermal conditions (PV = const.). Now the pressure inside the system is 2-δP < 2. Hence, for a gas molecule attempting to leave the system, there is higher resistance to go outside. Similarly, for a gas molecule entering, there is a net force pushing it into the system This continues till pressure is equalised. Assuming the environment is infinite, there is no way to expand he volume to  halve the pressure. \\r\\n\\r\\nSince the pressure inside and outside the system is the same, the gas molecules will never spontaneously leave the system such that pressure inside is half of the environment pressure. \\r\\n\\r\\nHence, there is no possible way for the system and environment to be in equilibrium in a state where the pressure of the system is 1atm and the environment is 2atm. With the system, the only equilibrium is possible at 2 atm no matter how the change is carries, as we are allowing the change of 2 quantities, n, the number of moles and V, the volume. Hence, the two will balance themselves out. \\r\\nHence equilibrium at the given final state can never be achieved.']", 'a', 0, 11201))
20
